diff --git a/src/sage/doctest/control.py b/src/sage/doctest/control.py
index d67b556..9d44bab 100644
--- a/src/sage/doctest/control.py
+++ b/src/sage/doctest/control.py
@@ -563,27 +563,9 @@ class DocTestController(SageObject):
 
     def test_safe_directory(self, dir=None):
         """
-        Test that the given directory is safe to run Python code from.
-
-        We use the check added to Python for this, which gives a
-        warning when the current directory is considered unsafe.  We promote
-        this warning to an error with ``-Werror``.  See
-        ``sage/tests/cmdline.py`` for a doctest that this works, see
-        also :trac:`13579`.
-
-        TESTS::
-
-            sage: from sage.doctest.control import DocTestDefaults, DocTestController
-            sage: DD = DocTestDefaults()
-            sage: DC = DocTestController(DD, [])
-            sage: DC.test_safe_directory()
-            sage: d = os.path.join(tmp_dir(), "test")
-            sage: os.mkdir(d)
-            sage: os.chmod(d, 0o777)
-            sage: DC.test_safe_directory(d)
-            Traceback (most recent call last):
-            ...
-            RuntimeError: refusing to run doctests...
+        This doesn't work with every version of python, but is not necessary with
+        nix anyways (since the doctests will never be run from a world-writeable
+        dir).
         """
         import subprocess
         with open(os.devnull, 'w') as dev_null:
diff --git a/src/sage/tests/cmdline.py b/src/sage/tests/cmdline.py
index fba42cb..8f11599 100644
--- a/src/sage/tests/cmdline.py
+++ b/src/sage/tests/cmdline.py
@@ -398,24 +398,6 @@ def test_executable(args, input="", timeout=100.0, **kwds):
         sage: ret
         1
 
-    Check that Sage refuses to run doctests from a directory whose
-    permissions are too loose.  We create a world-writable directory
-    inside a safe temporary directory to test this::
-
-        sage: d = os.path.join(tmp_dir(), "test")
-        sage: os.mkdir(d)
-        sage: os.chmod(d, 0o777)
-        sage: (out, err, ret) = test_executable(["sage", "-t", "nonexisting.py"], cwd=d)
-        sage: print(err)
-        Traceback (most recent call last):
-        ...
-        RuntimeError: refusing to run doctests...
-        sage: (out, err, ret) = test_executable(["sage", "-tp", "1", "nonexisting.py"], cwd=d)
-        sage: print(err)
-        Traceback (most recent call last):
-        ...
-        RuntimeError: refusing to run doctests...
-
     Now run a test for the fixdoctests script and, in particular, check that the
     issues raised in :trac:`10589` are fixed. We have to go to slightly silly
     lengths to doctest the output.::
